# 第十一章 测试

Created: November 14, 2021 10:55 AM
Created by: Anonymous
Last edited time: November 18, 2021 9:41 PM

Rust 会进行所有目前我们已经见过的类型检查和借用检查。但是并不会对程序的逻辑结果进行检查，这里就需要测试出场了。

# 11.1 如何编写测试

Rust 中的测试函数是用来验证非测试代码是否按照期望的方式运行的。测试函数体通常执行如下三种操作：

1. 设置任何所需的数据或状态
2. 运行需要测试的代码
3. 断言其结果是我们所期望的

## 测试函数剖析

### 1. 测试成功的测试结果

当我们新建一个项目adder时，使用命令：`cargo new adder --lib`

adder库中的lib.rs的内容如下：

```rust
#[cfg(test)]
mod tests {
    #[test]
    fn it_works() {
        assert_eq!(2 + 2, 4);
    }
}
```

接着我们切换到这个目录：`cd adder` ，运行`cargo test` ，运行结果如下：

```rust
E:\demo\rust\guessing_game\adder>cargo test
   Compiling adder v0.1.0 (E:\demo\rust\guessing_game\adder)
    Finished test [unoptimized + debuginfo] target(s) in 1.89s
     Running unittests (target\debug\deps\adder-192069719eb6464f.exe)

running 1 test
test tests::it_works ... ok

test result: ok. 1 passed; 0 failed; 0 ignored; 0 measured; 0 filtered out; finished in 0.00s

   Doc-tests adder

running 0 tests

test result: ok. 0 passed; 0 failed; 0 ignored; 0 measured; 0 filtered out; finished in 0.00s
```

下面我们分析一下上面的这块输出：

这一段是编译运行的信息：

```rust
E:\demo\rust\guessing_game\adder>cargo test
   Compiling adder v0.1.0 (E:\demo\rust\guessing_game\adder)
    Finished test [unoptimized + debuginfo] target(s) in 1.89s
     Running unittests (target\debug\deps\adder-192069719eb6464f.exe)
```

生成测试函数的名称：

```rust
running 1 test
test tests::it_works ... ok
```

测试运行结果的摘要：

```rust
test result: ok. 1 passed; 0 failed; 0 ignored; 0 measured; 0 filtered out; finished in 0.00s
```

其中：

1. `test result: ok.` ：表示所有测试都通过
2. `1 passed; 0 failed;` ：表示通过或失败的测试数量
3. `0 ignored;` ：表示标记为忽略的测试数量
4. `0 measured;` ：针对性能测试
5. `0 filtered out;` ：需要过滤运行的测试数量
6. `finished in 0.00s` ：测试运行结束的时间

文档测试的结果：

```rust
   Doc-tests adder

running 0 tests

test result: ok. 0 passed; 0 failed; 0 ignored; 0 measured; 0 filtered out; finished in 0.00s
```

### 2. 测试失败的测试结果

adder库中的lib.rs的内容修改如下：

将测试函数`it_works`的函数名改为了`exploration`

```rust
#[cfg(test)]
mod tests {
    #[test]
    fn exploration() {
        assert_eq!(2 + 2, 4);
    }

    #[test]
    fn another() {
        panic!("Make this test fail");
    }
}
```

`cargo test` 运行输出：

```rust
E:\demo\rust\guessing_game\adder>cargo test
   Compiling adder v0.1.0 (E:\demo\rust\guessing_game\adder)
    Finished test [unoptimized + debuginfo] target(s) in 0.66s
     Running unittests (target\debug\deps\adder-192069719eb6464f.exe)

running 2 tests
test tests::exploration ... ok
test tests::another ... FAILED

failures:

---- tests::another stdout ----
thread 'tests::another' panicked at 'Make this test fail', src\lib.rs:10:9
note: run with `RUST_BACKTRACE=1` environment variable to display a backtrace

failures:
    tests::another

test result: FAILED. 1 passed; 1 failed; 0 ignored; 0 measured; 0 filtered out; finished in 0.00s
```

这里我们看到测试输出又发生了进一步的变化。

- `test tests::exploration ... ok`：因为函数名称的修改发生了变化
- `test tests::another ... FAILED`：another函数测试失败的输出，rust会为每一个测试函数新建一个测试线程
- 第一个`failures`：是失败的详细原因
- 第二个`failures`：是测试失败的函数
- `test result: FAILED.`：是总体的测试结果

## 使用assert!宏来检查结果

下面的这段程序，我们比较两个长方形，大的是否能包住小的。

```rust
#[derive(Debug)]
struct Rectangle {
    width: u32,
    height: u32,
}

impl Rectangle {
    fn can_hold(&self, other: &Rectangle) -> bool {
        self.width > other.width && self.height > other.height
    }
}

#[cfg(test)]
mod tests {
    use super::*;

    #[test]
    fn larger_can_hold_smaller() {
        let larger = Rectangle { width: 8, height: 7 };
        let smaller = Rectangle { width: 5, height: 1 };
        let larger2 = Rectangle{ width: 8, height: 8};

        assert!(larger.can_hold(&smaller), "大的长方形保不住小的长方形");
        assert!(larger.can_hold(&larger2), "大的长方形保不住小的长方形");
    }
}
```

`cargo test` 运行输出：

```rust
E:\demo\rust\guessing_game\adder>cargo test
   Compiling adder v0.1.0 (E:\demo\rust\guessing_game\adder)
    Finished test [unoptimized + debuginfo] target(s) in 0.79s
     Running unittests (target\debug\deps\adder-192069719eb6464f.exe)

running 1 test
test tests::larger_can_hold_smaller ... FAILED

failures:

---- tests::larger_can_hold_smaller stdout ----
thread 'tests::larger_can_hold_smaller' panicked at '大的长方形保不住小的长方形', src\lib.rs:38:9
note: run with `RUST_BACKTRACE=1` environment variable to display a backtrace

failures:
    tests::larger_can_hold_smaller

test result: FAILED. 0 passed; 1 failed; 0 ignored; 0 measured; 0 filtered out; finished in 0.00s
```

`assert!`宏要说的有两点：

1. 第一个参数是一个`bool`类型
2. 如果第一个参数是`false`，我们可以自定义失败信息，来显式的标注错误

除了这些，还有一点：`use super::*;`。adder是一个内部模块，要测试外部模块中的代码，需要将其引入到内部模块的作用域中。这里选择使用 glob 全局导入，以便在 `tests` 模块中使用所有在外部模块定义的内容。

## 使用assert_eq!和assert_ne!宏来测试相等

`assert_eq!`是用来比较两个值相等的，如果相等则测试通过，`assert_ne!`反之。

当断言失败时他们也会打印出这两个值具体是什么，以便于观察测试 **为什么** 失败。`assert!`却不会。

示例代码：

```rust
pub fn add_two(a: i32) -> i32 {
    a + 2
}

#[cfg(test)]
mod tests {
    use super::*;

    #[test]
    fn it_adds_two() {
        assert_eq!(5, add_two(2), "错了错了");
    }
}
```

`cargo test` 运行输出：

```rust
E:\demo\rust\guessing_game\adder>cargo test
   Compiling adder v0.1.0 (E:\demo\rust\guessing_game\adder)
    Finished test [unoptimized + debuginfo] target(s) in 0.54s
     Running unittests (target\debug\deps\adder-192069719eb6464f.exe)

running 1 test
test tests::it_adds_two ... FAILED

failures:

---- tests::it_adds_two stdout ----
thread 'tests::it_adds_two' panicked at 'assertion failed: `(left == right)`
  left: `5`,
 right: `4`: 错了错了', src\lib.rs:52:9
note: run with `RUST_BACKTRACE=1` environment variable to display a backtrace

failures:
    tests::it_adds_two

test result: FAILED. 0 passed; 1 failed; 0 ignored; 0 measured; 0 filtered out; finished in 0.00s
```

## 使用should_panic检查panic

检查代码是否按照期望处理错误也很重要。可以通过对函数增加另一个属性 `should_panic` 来实现这些。这个属性在函数中的代码 panic 时会通过，而在其中的代码没有 panic 时失败。

### 1. 测试成功情况

```rust
pub struct Guess {
    value: i32,
}

impl Guess {
    pub fn new(value: i32) -> Guess {
        if value < 1 || value > 100 {
            panic!("Guess value must be between 1 and 100, got {}.", value);
        }

        Guess {
            value
        }
    }
}

#[cfg(test)]
mod tests {
    use super::*;

    #[test]
    #[should_panic]
    fn greater_than_100() {
        Guess::new(200);
    }
}
```

`cargo test` 运行输出：

```rust
E:\demo\rust\guessing_game\adder>cargo test
   Compiling adder v0.1.0 (E:\demo\rust\guessing_game\adder)
    Finished test [unoptimized + debuginfo] target(s) in 0.58s
     Running unittests (target\debug\deps\adder-192069719eb6464f.exe)

running 1 test
test tests::greater_than_100 ... ok

test result: ok. 1 passed; 0 failed; 0 ignored; 0 measured; 0 filtered out; finished in 0.00s

   Doc-tests adder

running 0 tests

test result: ok. 0 passed; 0 failed; 0 ignored; 0 measured; 0 filtered out; finished in 0.00s
```

### 2. 测试失败情况

我们将new方法原有的`value>100`的判断去除。

```rust
pub struct Guess {
    value: i32,
}

impl Guess {
    pub fn new(value: i32) -> Guess {
        if value < 1 {
            panic!("Guess value must be between 1 and 100, got {}.", value);
        }

        Guess {
            value
        }
    }
}

#[cfg(test)]
mod tests {
    use super::*;

    #[test]
    #[should_panic]
    fn greater_than_100() {
        Guess::new(200);
    }
}
```

`cargo test` 运行输出：

```rust
E:\demo\rust\guessing_game\adder>cargo test
   Compiling adder v0.1.0 (E:\demo\rust\guessing_game\adder)
    Finished test [unoptimized + debuginfo] target(s) in 0.61s
     Running unittests (target\debug\deps\adder-192069719eb6464f.exe)

running 1 test
test tests::greater_than_100 ... FAILED

failures:

---- tests::greater_than_100 stdout ----
note: test did not panic as expected

failures:
    tests::greater_than_100

test result: FAILED. 0 passed; 1 failed; 0 ignored; 0 measured; 0 filtered out; finished in 0.00s
```

从输出的报错信息看，测试并没有出现期望的panic。但是具体的报错信息却没有显式的打印出来。

### 3. 增加expected参数

给should_panic添加expected参数。

```rust
pub struct Guess {
    value: i32,
}

impl Guess {
    pub fn new(value: i32) -> Guess {
        if value < 1 {
            panic!("Guess value must be greater than or equal to 1, got {}.",
                   value);
        } else if value > 100 {
            panic!("Guess value must be less than or equal to 100, got {}.",
                   value);
        }

        Guess {
            value
        }
    }
}

#[cfg(test)]
mod tests {
    use super::*;

    #[test]
    #[should_panic(expected = "Guess value must be less than or equal to 100")]
    fn greater_than_100() {
        Guess::new(200);
    }
}
```

`cargo test` 运行输出：

```rust
E:\demo\rust\guessing_game\adder>cargo test
   Compiling adder v0.1.0 (E:\demo\rust\guessing_game\adder)
    Finished test [unoptimized + debuginfo] target(s) in 0.63s
     Running unittests (target\debug\deps\adder-192069719eb6464f.exe)

running 1 test
test tests::greater_than_100 ... ok

test result: ok. 1 passed; 0 failed; 0 ignored; 0 measured; 0 filtered out; finished in 0.00s

   Doc-tests adder

running 0 tests

test result: ok. 0 passed; 0 failed; 0 ignored; 0 measured; 0 filtered out; finished in 0.00s
```

这里我们看到这段should_panic确实测试通过了，下面我们模拟一下测试失败的情况：

```rust
pub struct Guess {
    value: i32,
}

impl Guess {
    pub fn new(value: i32) -> Guess {
        if value < 1 {
            panic!("Guess value must be less than or equal to 100, got {}.",
                   value);
        } else if value > 100 {
            panic!("Guess value must be greater than or equal to 1, got {}.",
                   value);
        }

        Guess {
            value
        }
    }
}

#[cfg(test)]
mod tests {
    use super::*;

    #[test]
    #[should_panic(expected = "Guess value must be less than or equal to 100")]
    fn greater_than_100() {
        Guess::new(200);
    }
}
```

`cargo test` 运行输出：

```rust
E:\demo\rust\guessing_game\adder>cargo test
   Compiling adder v0.1.0 (E:\demo\rust\guessing_game\adder)
    Finished test [unoptimized + debuginfo] target(s) in 0.56s
     Running unittests (target\debug\deps\adder-192069719eb6464f.exe)

running 1 test
test tests::greater_than_100 ... FAILED

failures:

---- tests::greater_than_100 stdout ----
thread 'tests::greater_than_100' panicked at 'Guess value must be greater than or equal to 1, got 200.', src\lib.rs:151:13
note: run with `RUST_BACKTRACE=1` environment variable to display a backtrace
note: panic did not contain expected string
      panic message: `"Guess value must be greater than or equal to 1, got 200."`,
 expected substring: `"Guess value must be less than or equal to 100"`

failures:
    tests::greater_than_100

test result: FAILED. 0 passed; 1 failed; 0 ignored; 0 measured; 0 filtered out; finished in 0.00s
```

可以从输出中看到对于错误的期望信息比对不一致导致了上面的报错。这样就方便我们查找错误的原因了。

## 将 Result<T, E> 用于测试

不同于调用 `assert_eq!` 宏，`Result<T, E>`在测试通过时返回`Ok(())`，在测试失败时返回带有`String`的`Err` 。

不能对这些使用 `Result<T, E>` 的测试使用 `#[should_panic]` 注解。相反应该在测试失败时直接返回 `Err` 值。

```rust
#[cfg(test)]
mod tests {
    #[test]
    fn it_works() -> Result<(), String> {
        if 2 + 2 == 4 {
            Ok(())
        } else {
            Err(String::from("two plus two does not equal four"))
        }
    }

    #[test]
    fn it_works_no() -> Result<(), String> {
        if 2 + 3 == 4 {
            Ok(())
        } else {
            Err(String::from("two plus two does not equal four"))
        }
    }
}
```

`cargo test` 运行输出：

```rust
E:\demo\rust\guessing_game\adder>cargo test
   Compiling adder v0.1.0 (E:\demo\rust\guessing_game\adder)
    Finished test [unoptimized + debuginfo] target(s) in 0.72s
     Running unittests (target\debug\deps\adder-192069719eb6464f.exe)

running 2 tests
test tests::it_works ... ok
test tests::it_works_no ... FAILED

failures:

---- tests::it_works_no stdout ----
Error: "two plus two does not equal four"
thread 'tests::it_works_no' panicked at 'assertion failed: `(left == right)`
  left: `1`,
 right: `0`: the test returned a termination value with a non-zero status code (1) which indicates a failure', C:\U
sers\depers\.rustup\toolchains\stable-x86_64-pc-windows-msvc\lib/rustlib/src/rust\library\test\src\lib.rs:193:5
note: run with `RUST_BACKTRACE=1` environment variable to display a backtrace

failures:
    tests::it_works_no

test result: FAILED. 1 passed; 1 failed; 0 ignored; 0 measured; 0 filtered out; finished in 0.00s
```

# 11.2 运行测试

通过`cargo test -- --help`命令，我们可以查看更多控制测试的参数。

## 并行或连续的运行测试

当运行多个测试时， Rust 默认使用线程来并行运行。这意味着测试会更快地运行完毕，所以你可以更快的得到代码能否工作的反馈。

如果你想并行的运行测试，或者想要更加精确的控制线程的数量。可以使用如下命令，串行的一个一个运行测试方法：

```rust
$ cargo test -- --test-threads=1
```

## 显示函数输出

下面这段例子中，默认情况下测试通过是不会显示输出代码中的`println`输出的，测试失败情况下才会输出。

```rust
fn prints_and_returns_10(a: i32) -> i32 {
    println!("I got the value {}", a);
    10
}

#[cfg(test)]
mod tests {
    use super::*;

    #[test]
    fn this_test_will_pass() {
        let value = prints_and_returns_10(4);
        assert_eq!(10, value);
    }

    #[test]
    fn this_test_will_fail() {
        let value = prints_and_returns_10(8);
        assert_eq!(5, value);
    }
}
```

使用cargo test，运行输出：

```rust
E:\demo\rust\guessing_game\adder>cargo test
   Compiling adder v0.1.0 (E:\demo\rust\guessing_game\adder)
    Finished test [unoptimized + debuginfo] target(s) in 2.58s
     Running unittests (target\debug\deps\adder-192069719eb6464f.exe)

running 2 tests
test tests::this_test_will_pass ... ok
test tests::this_test_will_fail ... FAILED

failures:

---- tests::this_test_will_fail stdout ----
I got the value 8
thread 'tests::this_test_will_fail' panicked at 'assertion failed: `(left == right)`
  left: `5`,
 right: `10`', src\lib.rs:214:9
note: run with `RUST_BACKTRACE=1` environment variable to display a backtrace

failures:
    tests::this_test_will_fail

test result: FAILED. 1 passed; 1 failed; 0 ignored; 0 measured; 0 filtered out; finished in 0.00s
```

如果想控制运行测试显示的输出所有的打印输出，使用命令：

```rust
$ cargo test -- --nocapture
```

使用上面的命令运行输出如下：

```rust
E:\demo\rust\guessing_game\adder>cargo test -- --nocapture
    Finished test [unoptimized + debuginfo] target(s) in 0.04s
     Running unittests (target\debug\deps\adder-192069719eb6464f.exe)

running 2 tests
I got the value 8
thread 'I got the value 4
tests::this_test_will_failtest tests::this_test_will_pass ... ' panicked at 'okassertion failed: `(left == right)`
  left: `5`,
 right: `10`
', src\lib.rs:214:9
note: run with `RUST_BACKTRACE=1` environment variable to display a backtrace
test tests::this_test_will_fail ... FAILED

failures:

failures:
    tests::this_test_will_fail

test result: FAILED. 1 passed; 1 failed; 0 ignored; 0 measured; 0 filtered out; finished in 0.00s
```

## 通过指定的名称运行测试

示例程序：

```rust
pub fn add_two(a: i32) -> i32 {
    a + 2
}

#[cfg(test)]
mod tests {
    use super::*;

    #[test]
    fn add_two_and_two() {
        assert_eq!(4, add_two(2));
    }

    #[test]
    fn add_three_and_two() {
        assert_eq!(5, add_two(3));
    }

    #[test]
    fn one_hundred() {
        assert_eq!(102, add_two(100));
    }
}
```

### 1. 运行单个测试

使用`cargo test <测试名称>` ，这样我们就可以运行特定的测试。

```rust
E:\demo\rust\guessing_game\adder>cargo test one_hundred
   Compiling adder v0.1.0 (E:\demo\rust\guessing_game\adder)
    Finished test [unoptimized + debuginfo] target(s) in 0.68s
     Running unittests (target\debug\deps\adder-192069719eb6464f.exe)

running 1 test
test tests::one_hundred ... ok

test result: ok. 1 passed; 0 failed; 0 ignored; 0 measured; 2 filtered out; finished in 0.00s
```

### 2. 过滤运行多个测试

使用`cargo test <部分测试名称>` ，这样我们就可以运行多个相同开头名称的测试。

```rust
E:\demo\rust\guessing_game\adder>cargo test add
    Finished test [unoptimized + debuginfo] target(s) in 0.03s
     Running unittests (target\debug\deps\adder-192069719eb6464f.exe)

running 2 tests
test tests::add_three_and_two ... ok
test tests::add_two_and_two ... ok

test result: ok. 2 passed; 0 failed; 0 ignored; 0 measured; 1 filtered out; finished in 0.00s
```

### 3. 忽略某些测试

执行`cargo test`就会忽略`expensive_test`测试。

```rust
#[cfg(test)]
mod tests{
    #[test]
    fn it_works() {
        assert_eq!(2 + 2, 4);
    }

    #[test]
    #[ignore]
    fn expensive_test() {
        // 需要运行一个小时的代码
    }
}
```

运行输出：

```rust
E:\demo\rust\guessing_game\adder>cargo test
   Compiling adder v0.1.0 (E:\demo\rust\guessing_game\adder)
    Finished test [unoptimized + debuginfo] target(s) in 0.57s
     Running unittests (target\debug\deps\adder-192069719eb6464f.exe)

running 2 tests
test tests::expensive_test ... ignored
test tests::it_works ... ok

test result: ok. 1 passed; 0 failed; 1 ignored; 0 measured; 0 filtered out; finished in 0.00s
```

只希望运行被忽略的测试，可以使用 `cargo test -- --ignored` ，运行输出如下：

```rust
E:\demo\rust\guessing_game\adder>cargo test -- --ignored
    Finished test [unoptimized + debuginfo] target(s) in 0.03s
     Running unittests (target\debug\deps\adder-192069719eb6464f.exe)

running 1 test
test tests::expensive_test ... ok

test result: ok. 1 passed; 0 failed; 0 ignored; 0 measured; 1 filtered out; finished in 0.00
```

# 10.3 测试的组织结构

- 单元测试倾向于更小而更集中，在隔离的环境中一次测试一个模块，或者是测试私有接口。
- 集成测试对于你的库来说则完全是外部的。同其他使用库的代码一样使用库文件，也就是说它们只能调用一部分库中的公有 API 。集成测试的目的是测试库的多个部分能否一起正常工作。只测试公有接口而且每个测试都有可能会测试多个模块。

## 单元测试

### 1. 测试模块和 `#[cfg(test)]`

测试模块的 `#[cfg(test)]` 注解告诉 Rust 只在执行 `cargo test` 时才编译和运行测试代码，而在运行 `cargo build` 时不这么做。如下面的代码：

```rust
#[cfg(test)]
mod tests {
    #[test]
    fn it_works() {
        assert_eq!(2 + 2, 4);
    }
}
```

- cfg：代表 *configuration。*它告诉 Rust 其之后的项只应该被包含进特定配置选项中。
- test：配置选项是 `test`，即 Rust 所提供的用于编译和运行测试的配置选项。
- #[test]：标注需要测试的函数。

### 2. 测试私有函数

这里的私有函数指的就是没有标注`pub`关键字的函数，Rust允许测试私有函数。如下代码中的`internal`函数：

```rust
fn main() {}

pub fn add_two(a: i32) -> i32 {
    internal_adder(a, 2)
}

fn internal_adder(a: i32, b: i32) -> i32 {
    a + b
}

#[cfg(test)]
mod tests {
    use super::*;

    #[test]
    fn internal() {
        assert_eq!(4, internal_adder(2, 2));
    }
}
```

## 集成测试

集成测试能够测试多个模块的代码逻辑。

### 1. tests目录

为了编写集成测试，需要在项目根目录创建一个 *tests* 目录，与 *src* 同级。Cargo 知道如何去寻找这个目录中的集成测试文件。接着可以随意在这个目录中创建任意多的测试文件，Cargo 会将每一个文件当作单独的 crate 来编译。

创建一个集成测试，新建一个文件 *tests/integration_test.rs。*

```rust
use adder;

#[test]
fn it_adds_two() {
    assert_eq!(4, adder::add_two(2));
}
```

- `use adder;`：因为每一个 `tests` 目录中的测试文件都是完全独立的 crate，所以需要在每一个文件中导入库。
- 没有标注`#[cfg(test)]` ：不需要标注，Rust自己会去识别。

上面代码的运行结果：

```rust
$ cargo test
   Compiling adder v0.1.0 (file:///projects/adder)
    Finished dev [unoptimized + debuginfo] target(s) in 0.31 secs
     Running target/debug/deps/adder-abcabcabc

running 1 test
test tests::internal ... ok

test result: ok. 1 passed; 0 failed; 0 ignored; 0 measured; 0 filtered out

     Running target/debug/deps/integration_test-ce99bcc2479f4607

running 1 test
test it_adds_two ... ok

test result: ok. 1 passed; 0 failed; 0 ignored; 0 measured; 0 filtered out

   Doc-tests adder

running 0 tests

test result: ok. 0 passed; 0 failed; 0 ignored; 0 measured; 0 filtered out
```

上面包括三部分的输出：单元测试、集成测试和文档测试。

指定特定的测试集合进行测试。使用`cargo test --test <集成测试文件名>` ：

```rust
$ cargo test --test integration_test
    Finished dev [unoptimized + debuginfo] target(s) in 0.0 secs
     Running target/debug/integration_test-952a27e0126bb565

running 1 test
test it_adds_two ... ok

test result: ok. 1 passed; 0 failed; 0 ignored; 0 measured; 0 filtered out
```

### 2. 集成测试中的子模块

在编写集成测试的过程中，我们在之前第七章中学过，我们可以将不同的模块拆分到各自的文件中，然后文件之间就可以共享相同的行为（函数调用），但是在集成测试中不行。

在编写集成测试的过程中，你可能会遇到一些通用的函数。我们可以在tests目录下创建一个common目录，并新建一个mod.rs。Rust识别到*tests/common/mod.rs，*就不会将其视为一个集成测试文件内容集成测试了。在集成测试文件中，我们就可以使用定义在子模块中的方法了。

```rust
pub fn setup() {
    // 编写特定库测试所需的代码
}
```

```rust
use adder;

mod common;

#[test]
fn it_adds_two() {
    common::setup();
    assert_eq!(4, adder::add_two(2));
}
```

### 3. 二进制crate的集成测试

如果项目是二进制 crate 并且只包含 *src/main.rs* 而没有 src/lib.rs（库create），不能在tests目录中创建他的集成测试。**因为只有库 crate 才会向其他 crate 暴露了可供调用和使用的函数；二进制 crate 是为了单独运行。**

为什么 Rust 二进制项目的结构明确采用 *src/main.rs* 调用 *src/lib.rs* 中的逻辑的方式？因为通过这种结构，集成测试 **就可以** 通过 `extern crate` 测试库 crate 中的主要功能了，而如果这些重要的功能没有问题的话，*src/main.rs* 中的少量代码也就会正常工作且不需要测试。